<?xml version="1.0" ?>
<robot name="GEN3_URDF_V12" version="1.0">
  <!-- <link name="world">
  </link>
  <joint name="Fix_world" type="fixed">
    <parent link="world" />
    <child link="Base_Link" />
  </joint> -->
  <link name="Base_Link">
    <inertial>
      <origin xyz="-0.000648 -0.000166 0.084487" rpy="0 0 0" />
      <mass value="0" />
      <inertia ixx="0.004622" ixy="9E-06" ixz="6E-05" iyy="0.004495" iyz="9E-06" izz="0.002079" />
    </inertial>
    <visual>
      <origin xyz="0 0 0" rpy="0 0 0" />
      <geometry>
        <mesh filename="meshes/base_link.obj" />
      </geometry>
      <material name="">
        <color rgba="0.75294 0.75294 0.75294 1" />
      </material>
    </visual>
    <collision>
      <origin xyz="0 0 0" rpy="0 0 0" />
      <geometry>
        <mesh filename="meshes/base_link.stl" />
      </geometry>
    </collision>
  </link>
  <link name="Shoulder_Link">
    <inertial>
      <origin xyz="-2.3E-05 -0.010364 -0.07336" rpy="0 0 0" />
      <mass value="1.3773" />
      <inertia ixx="0.00457" ixy="1E-06" ixz="2E-06" iyy="0.004831" iyz="0.000448" izz="0.001409" />
    </inertial>
    <visual>
      <origin xyz="0 0 0" rpy="0 0 0" />
      <geometry>
        <mesh filename="meshes/shoulder_link.obj" />
      </geometry>
      <material name="">
        <color rgba="0.75294 0.75294 0.75294 1" />
      </material>
    </visual>
    <collision>
      <origin xyz="0 0 0" rpy="0 0 0" />
      <geometry>
        <mesh filename="meshes/shoulder_link.stl" />
      </geometry>
    </collision>
  </link>
  <joint name="Actuator1" type="continuous">
    <origin xyz="0 0 0.15643" rpy="3.1416 2.7629E-18 -4.9305E-36" />
    <parent link="Base_Link" />
    <child link="Shoulder_Link" />
    <axis xyz="0 0 1" />
    <limit lower="-1000" upper="1000" effort="39" velocity="0.8727" />
  </joint>
  <link name="HalfArm1_Link">
    <inertial>
      <origin xyz="-4.4E-05 -0.09958 -0.013278" rpy="0 0 0" />
      <mass value="1.1636" />
      <inertia ixx="0.011088" ixy="5E-06" ixz="0" iyy="0.001072" iyz="-0.000691" izz="0.011255" />
    </inertial>
    <visual>
      <origin xyz="0 0 0" rpy="0 0 0" />
      <geometry>
        <mesh filename="meshes/half_arm_1_link.obj" />
      </geometry>
      <material name="">
        <color rgba="0.75294 0.75294 0.75294 1" />
      </material>
    </visual>
    <collision>
      <origin xyz="0 0 0" rpy="0 0 0" />
      <geometry>
        <mesh filename="meshes/half_arm_1_link.stl" />
      </geometry>
    </collision>
  </link>
  <joint name="Actuator2" type="revolute">
    <origin xyz="0 0.005375 -0.12838" rpy="1.5708 2.1343E-17 -1.1102E-16" />
    <parent link="Shoulder_Link" />
    <child link="HalfArm1_Link" />
    <axis xyz="0 0 1" />
    <limit lower="-2.41" upper="2.41" effort="39" velocity="0.8727" />
  </joint>
  <link name="HalfArm2_Link">
    <inertial>
      <origin xyz="-4.4E-05 -0.006641 -0.117892" rpy="0 0 0" />
      <mass value="1.1636" />
      <inertia ixx="0.010932" ixy="0" ixz="-7E-06" iyy="0.011127" iyz="0.000606" izz="0.001043" />
    </inertial>
    <visual>
      <origin xyz="0 0 0" rpy="0 0 0" />
      <geometry>
        <mesh filename="meshes/half_arm_2_link.obj" />
      </geometry>
      <material name="">
        <color rgba="0.75294 0.75294 0.75294 1" />
      </material>
    </visual>
    <collision>
      <origin xyz="0 0 0" rpy="0 0 0" />
      <geometry>
        <mesh filename="meshes/half_arm_2_link.stl" />
      </geometry>
    </collision>
  </link>
  <joint name="Actuator3" type="continuous">
    <origin xyz="0 -0.21038 -0.006375" rpy="-1.5708 1.2326E-32 -2.9122E-16" />
    <parent link="HalfArm1_Link" />
    <child link="HalfArm2_Link" />
    <axis xyz="0 0 1" />
    <limit lower="-1000" upper="1000" effort="39" velocity="0.8727" />
  </joint>
  <link name="ForeArm_Link">
    <inertial>
      <origin xyz="-1.8E-05 -0.075478 -0.015006" rpy="0 0 0" />
      <mass value="0.9302" />
      <inertia ixx="0.008147" ixy="-1E-06" ixz="0" iyy="0.000631" iyz="-0.0005" izz="0.008316" />
    </inertial>
    <visual>
      <origin xyz="0 0 0" rpy="0 0 0" />
      <geometry>
        <mesh filename="meshes/forearm_link.obj" />
      </geometry>
      <material name="">
        <color rgba="0.75294 0.75294 0.75294 1" />
      </material>
    </visual>
    <collision>
      <origin xyz="0 0 0" rpy="0 0 0" />
      <geometry>
        <mesh filename="meshes/forearm_link.stl" />
      </geometry>
    </collision>
  </link>
  <joint name="Actuator4" type="revolute">
    <origin xyz="0 0.006375 -0.21038" rpy="1.5708 -6.6954E-17 -1.6653E-16" />
    <parent link="HalfArm2_Link" />
    <child link="ForeArm_Link" />
    <axis xyz="0 0 1" />
    <limit lower="-2.66" upper="2.66" effort="39" velocity="0.8727" />
  </joint>
  <link name="SphericalWrist1_Link">
    <inertial>
      <origin xyz="1E-06 -0.009432 -0.063883" rpy="0 0 0" />
      <mass value="0.6781" />
      <inertia ixx="0.001596" ixy="0" ixz="0" iyy="0.001607" iyz="0.000256" izz="0.000399" />
    </inertial>
    <visual>
      <origin xyz="0 0 0" rpy="0 0 0" />
      <geometry>
        <mesh filename="meshes/spherical_wrist_1_link.obj" />
      </geometry>
      <material name="">
        <color rgba="0.75294 0.75294 0.75294 1" />
      </material>
    </visual>
    <collision>
      <origin xyz="0 0 0" rpy="0 0 0" />
      <geometry>
        <mesh filename="meshes/spherical_wrist_1_link.stl" />
      </geometry>
    </collision>
  </link>
  <joint name="Actuator5" type="continuous">
    <origin xyz="0 -0.20843 -0.006375" rpy="-1.5708 2.2204E-16 -6.373E-17" />
    <parent link="ForeArm_Link" />
    <child link="SphericalWrist1_Link" />
    <axis xyz="0 0 1" />
    <limit lower="-1000" upper="1000" effort="9" velocity="0.8727" />
  </joint>
  <link name="SphericalWrist2_Link">
    <inertial>
      <origin xyz="1E-06 -0.045483 -0.00965" rpy="0 0 0" />
      <mass value="0.6781" />
      <inertia ixx="0.001641" ixy="0" ixz="0" iyy="0.00041" iyz="-0.000278" izz="0.001641" />
    </inertial>
    <visual>
      <origin xyz="0 0 0" rpy="0 0 0" />
      <geometry>
        <mesh filename="meshes/spherical_wrist_2_link.obj" />
      </geometry>
      <material name="">
        <color rgba="0.75294 0.75294 0.75294 1" />
      </material>
    </visual>
    <collision>
      <origin xyz="0 0 0" rpy="0 0 0" />
      <geometry>
        <mesh filename="meshes/spherical_wrist_2_link.stl" />
      </geometry>
    </collision>
  </link>
  <joint name="Actuator6" type="revolute">
    <origin xyz="0 0.00017505 -0.10593" rpy="1.5708 9.2076E-28 -8.2157E-15" />
    <parent link="SphericalWrist1_Link" />
    <child link="SphericalWrist2_Link" />
    <axis xyz="0 0 1" />
    <limit lower="-2.23" upper="2.23" effort="9" velocity="0.8727" />
  </joint>
  <link name="Bracelet_Link">
    <inertial>
      <origin xyz="-0.000281 -0.011402 -0.029798" rpy="0 0 0" />
      <mass value="0.5006" />
      <inertia ixx="0.000587" ixy="3E-06" ixz="3E-06" iyy="0.000369" iyz="0.000118" izz="0.000609" />
    </inertial>
    <visual>
      <origin xyz="0 0 0" rpy="0 0 0" />
      <geometry>
        <mesh filename="meshes/bracelet_no_vision_link.obj" />
      </geometry>
      <material name="">
        <color rgba="0.75294 0.75294 0.75294 1" />
      </material>
    </visual>
    <collision>
      <origin xyz="0 0 0" rpy="0 0 0" />
      <geometry>
        <mesh filename="meshes/bracelet_no_vision_link.stl" />
      </geometry>
    </collision>
  </link>
  <joint name="Actuator7" type="continuous">
    <origin xyz="0 -0.10593 -0.00017505" rpy="-1.5708 -5.5511E-17 9.6396E-17" />
    <parent link="SphericalWrist2_Link" />
    <child link="Bracelet_Link" />
    <axis xyz="0 0 1" />
    <limit lower="-1000" upper="1000" effort="9" velocity="0.8727" />
  </joint>
  <link name="EndEffector_Link" />
  <joint name="EndEffector" type="fixed">
    <origin xyz="0 0 -0.0615250000000001" rpy="3.14159265358979 1.09937075168372E-32 0" />
    <parent link="Bracelet_Link" />
    <child link="EndEffector_Link" />
    <axis xyz="0 0 0" />
  </joint>
  
  <!-- <link name="Camera_Link" />
  <joint name="Camera" type="fixed">
    <origin xyz="0 0.05639 -0.00305" rpy="3.14159265358979 3.14159265358979 0" />
    <parent link="EndEffector_Link" />
    <child  link="Camera_Link" />
  </joint>
  <link name="Camera_Depth_Frame" />
  <joint name="Camera_Depth" type="fixed">
    <origin xyz="0.0275 0.066 -0.00305" rpy="3.14159265358979 3.14159265358979 0" />
    <parent link="EndEffector_Link" />
    <child  link="Camera_Depth_Frame" />
  </joint>
  <link name="Camera_Color_Frame" />
  <joint name="Camera_Color" type="fixed">
    <origin xyz="0 0.05639 -0.00305" rpy="3.14159265358979 3.14159265358979 0" />
    <parent link="EndEffector_Link" />
    <child  link="Camera_Color_Frame" />
  </joint> -->
  <link name="Tool_Frame"/>
  <joint name="Tool" type="fixed">
      <origin xyz="0 0 0.120" rpy="0 0 0" />
      <parent link="EndEffector_Link" />
      <child link="Tool_Frame" />
      <axis xyz="0 0 0" />
  </joint>

  <!-- On the first day, Darwin created the world -->
  <joint name="gripper_base_joint" type="fixed">
    <!--
    <parent link="end_effector_link"/>
  -->
    <parent link="Bracelet_Link"/>
    <child link="gripper_base"/>
    <origin rpy="1.5707 0.0 0.0" xyz="0.0 0.0 -0.0615250000000001"/>
    <!-- 1.57 -->
  </joint>

  <link name="gripper_base">
    <inertial>
      <origin rpy="0 0 0" xyz="6.91E-06 4.4117E-06 0.031656"/>
      <mass value="0.60831"/>
      <inertia ixx="0.0004596" ixy="1.5559E-09" ixz="1.397E-07" iyy="0.0005181" iyz="-1.0325E-11" izz="0.00036051"/>
    </inertial>
    <visual>
      <origin rpy="0 0 0" xyz="0 0 0"/>
      <geometry>
        <mesh filename="meshes/base_of_gripper.obj"/>
      </geometry>
      <material name="">
        <color rgba="0.89804 0.91765 0.92941 0.25"/>
      </material>
    </visual>
    <collision>
      <origin rpy="0 0 0" xyz="0 0 0"/>
      <geometry>
        <mesh filename="meshes/base_of_gripper.STL"/>
      </geometry>
    </collision>
  </link>
  <link name="gripper_right_spring_link">
    <inertial>
      <origin rpy="0 0 0" xyz="-9.7222E-12 0.028253 6.791E-10"/>
      <mass value="0.029951"/>
      <inertia ixx="1.5103E-05" ixy="-1.0709E-16" ixz="-2.654E-15" iyy="5.0789E-06" iyz="3.2666E-14" izz="1.0707E-05"/>
    </inertial>
    <visual>
      <origin rpy="0 0 0" xyz="0 0 0"/>
      <geometry>
        <mesh filename="meshes/right_spring_link.STL"/>
      </geometry>
      <material name="">
        <color rgba="0.89804 0.91765 0.92941 1"/>
      </material>
    </visual>
    <collision>
      <origin rpy="0 0 0" xyz="0 0 0"/>
      <geometry>
        <mesh filename="meshes/right_spring_link.STL"/>
      </geometry>
    </collision>
  </link>
  <joint name="gripper_right_spring_link_joint" type="fixed">
    <origin rpy="3.1416 0 0.6983" xyz="0.0127 -0.061307 0"/>
    <parent link="gripper_base"/>
    <child link="gripper_right_spring_link"/>
    <axis xyz="0 0 1"/>
    <limit effort="0" lower="0" upper="0.7854" velocity="0"/>
  </joint>
  <link name="gripper_left_spring_link">
    <inertial>
      <origin rpy="0 0 0" xyz="-8.05421701555176E-13 0.0282525952540491 7.27854432947014E-10"/>
      <mass value="0.0299513316731757"/>
      <inertia ixx="1.51025275365861E-05" ixy="1.3893966137107E-16" ixz="-5.21047318848845E-15" iyy="5.07891354120236E-06" iyz="3.47379370230503E-14" izz="1.0706817344978E-05"/>
    </inertial>
    <visual>
      <origin rpy="0 0 0" xyz="0 0 0"/>
      <geometry>
        <mesh filename="meshes/left_spring_link.STL"/>
      </geometry>
      <material name="">
        <color rgba="0.898039215686275 0.917647058823529 0.929411764705882 1"/>
      </material>
    </visual>
    <collision>
      <origin rpy="0 0 0" xyz="0 0 0"/>
      <geometry>
        <mesh filename="meshes/left_spring_link.STL"/>
      </geometry>
    </collision>
  </link>
  <joint name="gripper_left_spring_link_joint" type="fixed">
    <origin rpy="3.1416 0 -0.70092" xyz="-0.0127 -0.061307 0"/>
    <parent link="gripper_base"/>
    <child link="gripper_left_spring_link"/>
    <axis xyz="0 0 1"/>
    <limit effort="0" lower="-0.7854" upper="0" velocity="0"/>
  </joint>
  <link name="gripper_right_driver">
    <inertial>
      <origin rpy="0 0 0" xyz="0.0179377478479594 0.000926031753317007 -4.0741034207454E-11"/>
      <mass value="0.0184906489409923"/>
      <inertia ixx="6.79440339903172E-07" ixy="-2.0728790158877E-07" ixz="5.46290681974064E-15" iyy="3.45929623837714E-06" iyz="7.55029433009734E-15" izz="3.75009298146153E-06"/>
    </inertial>
    <visual>
      <origin rpy="0 0 0" xyz="0 0 0"/>
      <geometry>
        <mesh filename="meshes/right_driver.STL"/>
      </geometry>
      <material name="">
        <color rgba="0.898039215686275 0.917647058823529 0.929411764705882 1"/>
      </material>
    </visual>
    <collision>
      <origin rpy="0 0 0" xyz="0 0 0"/>
      <geometry>
        <mesh filename="meshes/right_driver.STL"/>
      </geometry>
    </collision>
  </link>
  <joint name="gripper_right_driver_joint" type="fixed">
    <origin rpy="3.1416 0 -0.019735" xyz="0.030601 -0.054792 0"/>
    <parent link="gripper_base"/>
    <child link="gripper_right_driver"/>
    <axis xyz="0 0 1"/>
    <limit effort="150" lower="-3.1416" upper="3.1416" velocity="0"/>
  </joint>
  <link name="gripper_right_coupler">
    <inertial>
      <origin rpy="0 0 0" xyz="-0.00277693278884095 0.0214010778170948 -2.64117771736162E-15"/>
      <mass value="0.0273093985570947"/>
      <inertia ixx="8.4351877262463E-06" ixy="8.05599897942411E-07" ixz="3.98563616297657E-19" iyy="2.33117687880373E-06" iyz="-6.91949626399278E-19" izz="6.9133328065108E-06"/>
    </inertial>
    <visual>
      <origin rpy="0 0 0" xyz="0 0 0"/>
      <geometry>
        <mesh filename="meshes/right_coupler.STL"/>
      </geometry>
      <material name="">
        <color rgba="0.898039215686275 0.917647058823529 0.929411764705882 1"/>
      </material>
    </visual>
    <collision>
      <origin rpy="0 0 0" xyz="0 0 0"/>
      <geometry>
        <mesh filename="meshes/right_coupler.STL"/>
      </geometry>
    </collision>
  </link>
  <joint name="gripper_right_coupler_joint" type="fixed">
    <origin rpy="0 0 -0.25804" xyz="0.031486 -0.0040855 0"/>
    <parent link="gripper_right_driver"/>
    <child link="gripper_right_coupler"/>
    <axis xyz="0 0 -1"/>
    <limit effort="0" lower="0.13" upper="0.79" velocity="0"/>
  </joint>
  <link name="gripper_right_follower">
    <inertial>
      <origin rpy="0 0 0" xyz="0.0118738800643238 0.013213950103123 -6.42371679073841E-16"/>
      <mass value="0.0195548943464751"/>
      <inertia ixx="3.99125345460037E-06" ixy="-9.32228708142781E-07" ixz="-1.06756339811242E-18" iyy="1.28831055431048E-06" iyz="-9.53069862405573E-19" izz="4.59174098263665E-06"/>
    </inertial>
    <visual>
      <origin rpy="0 0 0" xyz="0 0 0"/>
      <geometry>
        <mesh filename="meshes/right_follower.STL"/>
      </geometry>
      <material name="">
        <color rgba="0.898039215686275 0.917647058823529 0.929411764705882 1"/>
      </material>
    </visual>
    <collision>
      <origin rpy="0 0 0" xyz="0 0 0"/>
      <geometry>
        <mesh filename="meshes/right_follower.STL"/>
      </geometry>
    </collision>
  </link>
  <joint name="gripper_right_follower_joint" type="fixed">
    <origin rpy="3.1416 0 -2.9033" xyz="-0.0061148 0.047125 0"/>
    <parent link="gripper_right_coupler"/>
    <child link="gripper_right_follower"/>
    <axis xyz="0 0 1"/>
    <limit effort="0" lower="-3.1416" upper="3.1416" velocity="0"/>
  </joint>
  <link name="gripper_right_pad">
    <inertial>
      <origin rpy="0 0 0" xyz="0.000197179990555962 0.003 -5.73415880070697E-15"/>
      <mass value="0.0112846745192962"/>
      <inertia ixx="4.84198905594698E-07" ixy="1.17467826101044E-22" ixz="-2.69493952498347E-22" iyy="1.75287448520128E-06" iyz="3.01393554780919E-23" izz="1.33638362672235E-06"/>
    </inertial>
    <visual>
      <origin rpy="0 0 0" xyz="0 0 0"/>
      <geometry>
        <mesh filename="meshes/right_pad.STL"/>
      </geometry>
      <material name="">
        <color rgba="0.529411764705882 0.549019607843137 0.549019607843137 1"/>
      </material>
    </visual>
    <collision>
      <origin rpy="0 0 0" xyz="0 0 0"/>
      <geometry>
        <mesh filename="meshes/right_pad.STL"/>
      </geometry>
    </collision>
  </link>
  <joint name="gripper_right_pad_joint" type="fixed">
    <origin rpy="3.1416 0 -1.5708" xyz="0.024903 0.032264 0"/>
    <parent link="gripper_right_follower"/>
    <child link="gripper_right_pad"/>
    <axis xyz="0 0 0"/>
  </joint>
  <link name="gripper_left_driver">
    <inertial>
      <origin rpy="0 0 0" xyz="0.0179377478480944 0.000926031754016808 -4.09476305946672E-11"/>
      <mass value="0.0184906489414316"/>
      <inertia ixx="6.79440340033055E-07" ixy="-2.07287901659297E-07" ixz="5.48822371152932E-15" iyy="3.45929623843939E-06" iyz="7.56200742857023E-15" izz="3.75009298156646E-06"/>
    </inertial>
    <visual>
      <origin rpy="0 0 0" xyz="0 0 0"/>
      <geometry>
        <mesh filename="meshes/left_driver.STL"/>
      </geometry>
      <material name="">
        <color rgba="0.898039215686275 0.917647058823529 0.929411764705882 1"/>
      </material>
    </visual>
    <collision>
      <origin rpy="0 0 0" xyz="0 0 0"/>
      <geometry>
        <mesh filename="meshes/left_driver.STL"/>
      </geometry>
    </collision>
  </link>
  <joint name="gripper_left_driver_joint" type="fixed">
    <origin rpy="0 0 -3.1245" xyz="-0.030601 -0.054792 0"/>
    <parent link="gripper_base"/>
    <child link="gripper_left_driver"/>
    <axis xyz="0 0 1"/>
    <limit effort="150" lower="-3.1416" upper="3.1416" velocity="0"/>
  </joint>
  <link name="gripper_left_coupler">
    <inertial>
      <origin rpy="0 0 0" xyz="-0.00277693278884093 0.0214010778170948 -2.65696393157366E-15"/>
      <mass value="0.0273093985570947"/>
      <inertia ixx="8.43518772624629E-06" ixy="8.05599897942414E-07" ixz="3.98028057558574E-19" iyy="2.33117687880373E-06" iyz="-6.91715450328278E-19" izz="6.9133328065108E-06"/>
    </inertial>
    <visual>
      <origin rpy="0 0 0" xyz="0 0 0"/>
      <geometry>
        <mesh filename="meshes/left_coupler.STL"/>
      </geometry>
      <material name="">
        <color rgba="0.898039215686275 0.917647058823529 0.929411764705882 1"/>
      </material>
    </visual>
    <collision>
      <origin rpy="0 0 0" xyz="0 0 0"/>
      <geometry>
        <mesh filename="meshes/left_coupler.STL"/>
      </geometry>
    </collision>
  </link>
  <joint name="gripper_left_coupler_joint" type="fixed">
    <origin rpy="3.1416 0 -3.1416" xyz="0.031486 -0.0040855 0"/>
    <parent link="gripper_left_driver"/>
    <child link="gripper_left_coupler"/>
    <axis xyz="0 0 1"/>
    <limit effort="0" lower="0.13" upper="0.79" velocity="0"/>
  </joint>
  <link name="gripper_left_follower">
    <inertial>
      <origin rpy="0 0 0" xyz="0.0118738800643238 0.013213950103123 2.13813023929037E-15"/>
      <mass value="0.0195548943464751"/>
      <inertia ixx="3.99125345460038E-06" ixy="-9.32228708142783E-07" ixz="-1.06843707618223E-18" iyy="1.28831055431048E-06" iyz="-9.54631781105362E-19" izz="4.59174098263666E-06"/>
    </inertial>
    <visual>
      <origin rpy="0 0 0" xyz="0 0 0"/>
      <geometry>
        <mesh filename="meshes/left_follower.STL"/>
      </geometry>
      <material name="">
        <color rgba="0.898039215686275 0.917647058823529 0.929411764705882 1"/>
      </material>
    </visual>
    <collision>
      <origin rpy="0 0 0" xyz="0 0 0"/>
      <geometry>
        <mesh filename="meshes/left_follower.STL"/>
      </geometry>
    </collision>
  </link>
  <joint name="gripper_left_follower_joint" type="fixed">
    <origin rpy="0 0 0.017192" xyz="-0.0061148 0.047125 0"/>
    <parent link="gripper_left_coupler"/>
    <child link="gripper_left_follower"/>
    <axis xyz="0 0 1"/>
    <limit effort="0" lower="-3.1416" upper="3.1416" velocity="0"/>
  </joint>
  <link name="gripper_left_pad">
    <inertial>
      <origin rpy="0 0 0" xyz="0.00019717999055599 0.003 8.49842392779646E-15"/>
      <mass value="0.0112846745192961"/>
      <inertia ixx="4.84198905594697E-07" ixy="7.66025016740815E-22" ixz="4.8234593310579E-23" iyy="1.75287448520127E-06" iyz="-9.35905899337494E-24" izz="1.33638362672235E-06"/>
    </inertial>
    <visual>
      <origin rpy="0 0 0" xyz="0 0 0"/>
      <geometry>
        <mesh filename="meshes/left_pad.STL"/>
      </geometry>
      <material name="">
        <color rgba="0.529411764705882 0.549019607843137 0.549019607843137 1"/>
      </material>
    </visual>
    <collision>
      <origin rpy="0 0 0" xyz="0 0 0"/>
      <geometry>
        <mesh filename="meshes/left_pad.STL"/>
      </geometry>
    </collision>
  </link>
  <joint name="gripper_left_pad_joint" type="fixed">
    <origin rpy="0 0 -1.5708" xyz="0.018903 0.032265 0"/>
    <parent link="gripper_left_follower"/>
    <child link="gripper_left_pad"/>
    <axis xyz="0 0 0"/>
  </joint>
</robot>